{"timestamp":"2025-10-27T09:18:58.342547Z","level":"info","event":"DAG bundles loaded: dags-folder","logger":"airflow.dag_processing.bundles.manager.DagBundlesManager","filename":"manager.py","lineno":179}
{"timestamp":"2025-10-27T09:18:58.344577Z","level":"info","event":"Filling up the DagBag from /opt/airflow/dags/batch_data_server_dag.py","logger":"airflow.models.dagbag.DagBag","filename":"dagbag.py","lineno":593}
{"timestamp":"2025-10-27T09:18:58.566871Z","level":"error","event":"Task failed with exception","logger":"task","filename":"task_runner.py","lineno":994,"error_detail":[{"exc_type":"ConnectionError","exc_value":"HTTPConnectionPool(host='localhost', port=8080): Max retries exceeded with url: /api/v1/dags/batch_process_watcher_dag/dagRuns (Caused by NewConnectionError('<urllib3.connection.HTTPConnection object at 0x7f2434b4d190>: Failed to establish a new connection: [Errno 111] Connection refused'))","exc_notes":[],"syntax_error":null,"is_cause":false,"frames":[{"filename":"/home/airflow/.local/lib/python3.12/site-packages/airflow/sdk/execution_time/task_runner.py","lineno":920,"name":"run"},{"filename":"/home/airflow/.local/lib/python3.12/site-packages/airflow/sdk/execution_time/task_runner.py","lineno":1307,"name":"_execute_task"},{"filename":"/home/airflow/.local/lib/python3.12/site-packages/airflow/sdk/bases/operator.py","lineno":416,"name":"wrapper"},{"filename":"/home/airflow/.local/lib/python3.12/site-packages/airflow/providers/standard/operators/python.py","lineno":216,"name":"execute"},{"filename":"/home/airflow/.local/lib/python3.12/site-packages/airflow/providers/standard/operators/python.py","lineno":239,"name":"execute_callable"},{"filename":"/home/airflow/.local/lib/python3.12/site-packages/airflow/sdk/execution_time/callback_runner.py","lineno":82,"name":"run"},{"filename":"/opt/airflow/dags/batch_data_server_dag.py","lineno":70,"name":"trigger_next_dag"},{"filename":"/home/airflow/.local/lib/python3.12/site-packages/requests/api.py","lineno":115,"name":"post"},{"filename":"/home/airflow/.local/lib/python3.12/site-packages/requests/api.py","lineno":59,"name":"request"},{"filename":"/home/airflow/.local/lib/python3.12/site-packages/requests/sessions.py","lineno":589,"name":"request"},{"filename":"/home/airflow/.local/lib/python3.12/site-packages/requests/sessions.py","lineno":703,"name":"send"},{"filename":"/home/airflow/.local/lib/python3.12/site-packages/requests/adapters.py","lineno":677,"name":"send"}],"is_group":false,"exceptions":[]},{"exc_type":"MaxRetryError","exc_value":"HTTPConnectionPool(host='localhost', port=8080): Max retries exceeded with url: /api/v1/dags/batch_process_watcher_dag/dagRuns (Caused by NewConnectionError('<urllib3.connection.HTTPConnection object at 0x7f2434b4d190>: Failed to establish a new connection: [Errno 111] Connection refused'))","exc_notes":[],"syntax_error":null,"is_cause":false,"frames":[{"filename":"/home/airflow/.local/lib/python3.12/site-packages/requests/adapters.py","lineno":644,"name":"send"},{"filename":"/home/airflow/.local/lib/python3.12/site-packages/urllib3/connectionpool.py","lineno":841,"name":"urlopen"},{"filename":"/home/airflow/.local/lib/python3.12/site-packages/urllib3/util/retry.py","lineno":519,"name":"increment"}],"is_group":false,"exceptions":[]},{"exc_type":"NewConnectionError","exc_value":"<urllib3.connection.HTTPConnection object at 0x7f2434b4d190>: Failed to establish a new connection: [Errno 111] Connection refused","exc_notes":[],"syntax_error":null,"is_cause":true,"frames":[{"filename":"/home/airflow/.local/lib/python3.12/site-packages/urllib3/connectionpool.py","lineno":787,"name":"urlopen"},{"filename":"/home/airflow/.local/lib/python3.12/site-packages/urllib3/connectionpool.py","lineno":493,"name":"_make_request"},{"filename":"/home/airflow/.local/lib/python3.12/site-packages/urllib3/connection.py","lineno":494,"name":"request"},{"filename":"/usr/python/lib/python3.12/http/client.py","lineno":1333,"name":"endheaders"},{"filename":"/usr/python/lib/python3.12/http/client.py","lineno":1093,"name":"_send_output"},{"filename":"/usr/python/lib/python3.12/http/client.py","lineno":1037,"name":"send"},{"filename":"/home/airflow/.local/lib/python3.12/site-packages/urllib3/connection.py","lineno":325,"name":"connect"},{"filename":"/home/airflow/.local/lib/python3.12/site-packages/urllib3/connection.py","lineno":213,"name":"_new_conn"}],"is_group":false,"exceptions":[]},{"exc_type":"ConnectionRefusedError","exc_value":"[Errno 111] Connection refused","exc_notes":[],"syntax_error":null,"is_cause":true,"frames":[{"filename":"/home/airflow/.local/lib/python3.12/site-packages/urllib3/connection.py","lineno":198,"name":"_new_conn"},{"filename":"/home/airflow/.local/lib/python3.12/site-packages/urllib3/util/connection.py","lineno":85,"name":"create_connection"},{"filename":"/home/airflow/.local/lib/python3.12/site-packages/urllib3/util/connection.py","lineno":73,"name":"create_connection"}],"is_group":false,"exceptions":[]}]}
